<?xml version="1.0" ?>
<robot name="robot_arm">
    <disable_collisions link1="rotator1" link2="pivot1" reason="Adjacent" />
    <disable_collisions link1="pivot1" link2="arm1" reason="Adjacent" />
    <disable_collisions link1="arm1" link2="pivot1b" reason="Adjacent" />
    <disable_collisions link1="pivot1b" link2="arm1b" reason="Adjacent" />
    <disable_collisions link1="arm1b" link2="pivot2" reason="Adjacent" />
    <disable_collisions link1="pivot2" link2="arm2" reason="Adjacent" />
    <disable_collisions link1="sphere" link2="ALL" reason="NotNeeded" />
    <disable_collisions link1="needle" link2="ALL" reason="NotNeeded" />
    <link name="base_link">
        <visual>
            <geometry>
                <box size="4 4 1" />
            </geometry>
        </visual>
        <collision>
            <geometry>
                <box size="4 4 1" />
            </geometry>
        </collision>
        <inertial>
            <mass value="0.1" />
            <origin xyz="0 0 0" rpy="0 0 0" />
            <inertia ixx="0.03" iyy="0.03" izz="0.03" ixy="0.0" ixz="0.0" iyz="0.0" />
        </inertial>
    </link>
    <link name="rotator1">
        <visual>
            <geometry>
                <cylinder radius="2" length="1" />
            </geometry>
        </visual>
        <collision>
            <geometry>
                <cylinder radius="2" length="1" />
            </geometry>
        </collision>
        <inertial>
            <mass value="0.1" />
            <origin xyz="0 0 0" rpy="0 0 0" />
            <inertia ixx="0.03" iyy="0.03" izz="0.03" ixy="0.0" ixz="0.0" iyz="0.0" />
        </inertial>
    </link>
    <link name="pivot1">
        <visual>
            <origin xyz="0 0 0" rpy="0 1.57 0" />
            <geometry>
                <cylinder radius="1" length="1" />
            </geometry>
        </visual>
        <collision>
            <origin xyz="0 0 0" rpy="0 1.57 0" />
            <geometry>
                <cylinder radius="0.1" length="0.1" />
            </geometry>
        </collision>
        <inertial>
            <mass value="0.1" />
            <origin xyz="0 0 0" rpy="0 0 0" />
            <inertia ixx="0.03" iyy="0.03" izz="0.03" ixy="0.0" ixz="0.0" iyz="0.0" />
        </inertial>
    </link>
    <link name="arm1">
        <visual>
            <material name="blue">
                <color rgba="0 0 1 1" />
            </material>
            <origin xyz="0 0 3.75" rpy="0 0 0" />
            <geometry>
                <cylinder radius="0.5" length="5.5" />
            </geometry>
        </visual>
        <collision>
            <origin xyz="0 0 3.75" rpy="0 0 0" />
            <geometry>
                <cylinder radius="0.5" length="5.5" />
            </geometry>
        </collision>
        <inertial>
            <mass value="0.1" />
            <origin xyz="0 0 0" rpy="0 0 0" />
            <inertia ixx="0.03" iyy="0.03" izz="0.03" ixy="0.0" ixz="0.0" iyz="0.0" />
        </inertial>
    </link>
    <link name="pivot1b">
        <visual>
            <origin xyz="0 0 0" rpy="0 1.57 0" />
            <geometry>
                <cylinder radius="1" length="1" />
            </geometry>
        </visual>
        <collision>
            <origin xyz="0 0 0" rpy="0 1.57 0" />
            <geometry>
                <cylinder radius="0.1" length="0.1" />
            </geometry>
        </collision>
        <inertial>
            <mass value="0.1" />
            <origin xyz="0 0 0" rpy="0 0 0" />
            <inertia ixx="0.03" iyy="0.03" izz="0.03" ixy="0.0" ixz="0.0" iyz="0.0" />
        </inertial>
    </link>
    <link name="arm1b">
        <visual>
            <material name="blue">
                <color rgba="0 0 1 1" />
            </material>
            <origin xyz="0 0 3.75" rpy="0 0 0" />
            <geometry>
                <cylinder radius="0.5" length="5.5" />
            </geometry>
        </visual>
        <collision>
            <origin xyz="0 0 3.75" rpy="0 0 0" />
            <geometry>
                <cylinder radius="0.5" length="5.5" />
            </geometry>
        </collision>
        <inertial>
            <mass value="0.1" />
            <origin xyz="0 0 0" rpy="0 0 0" />
            <inertia ixx="0.03" iyy="0.03" izz="0.03" ixy="0.0" ixz="0.0" iyz="0.0" />
        </inertial>
    </link>
    <link name="pivot2">
        <visual>
            <origin xyz="0 0 0" rpy="0 1.57 0" />
            <geometry>
                <cylinder radius="1" length="1" />
            </geometry>
        </visual>
        <collision>
            <origin xyz="0 0 0" rpy="0 1.57 0" />
            <geometry>
                <cylinder radius="0.1" length="0.1" />
            </geometry>
        </collision>
        <inertial>
            <mass value="0.1" />
            <origin xyz="0 0 0" rpy="0 0 0" />
            <inertia ixx="0.03" iyy="0.03" izz="0.03" ixy="0.0" ixz="0.0" iyz="0.0" />
        </inertial>
    </link>
    <link name="arm2">
        <visual>
            <material name="blue">
                <color rgba="0 0 1 1" />
            </material>
            <origin xyz="0 0 2.5" rpy="0 0 0" />
            <geometry>
                <cylinder radius="0.5" length="3" />
            </geometry>
        </visual>
        <collision>
            <origin xyz="0 0 2.5" rpy="0 0 0" />
            <geometry>
                <cylinder radius="0.5" length="3" />
            </geometry>
        </collision>
        <inertial>
            <mass value="0.1" />
            <origin xyz="0 0 0" rpy="0 0 0" />
            <inertia ixx="0.03" iyy="0.03" izz="0.03" ixy="0.0" ixz="0.0" iyz="0.0" />
        </inertial>
    </link>
    <link name="sphere">
        <visual>
            <origin xyz="0 0 0" rpy="0 0 0" />
            <geometry>
                <sphere radius="0.6" />
            </geometry>
        </visual>
        <collision>
            <origin xyz="0 0 0" rpy="0 0 0" />
            <geometry>
                <sphere radius="0" />
            </geometry>
        </collision>
        <inertial>
            <mass value="0.1" />
            <origin xyz="0 0 0" rpy="0 0 0" />
            <inertia ixx="0.03" iyy="0.03" izz="0.03" ixy="0.0" ixz="0.0" iyz="0.0" />
        </inertial>
    </link>
    <link name="needle">
        <visual>
            <material name="gray">
                <color rgba="0.5 0.5 0.5 1" />
            </material>
            <origin xyz="0 0 -2" rpy="0 0 0" />
            <geometry>
                <cylinder radius="0.05" length="4" />
            </geometry>
        </visual>
        <collision>
            <origin xyz="0 0 0" rpy="0 0 0" />
            <geometry>
                <cylinder radius="0" length="0" />
            </geometry>
        </collision>
        <inertial>
            <mass value="0.1" />
            <origin xyz="0 0 0" rpy="0 0 0" />
            <inertia ixx="0.03" iyy="0.03" izz="0.03" ixy="0.0" ixz="0.0" iyz="0.0" />
        </inertial>
    </link>
    <joint name="base_link_to_rotator1" type="continuous">
        <origin xyz="0 0 1" rpy="0 0 0" />
        <axis xyz="0 0 1" />
        <parent link="base_link" />
        <child link="rotator1" />
    </joint>
    <joint name="rotator1_to_pivot1" type="fixed">
        <origin xyz="0 0 1.5" rpy="0 0 0" />
        <parent link="rotator1" />
        <child link="pivot1" />
    </joint>
    <joint name="pivot1_to_arm1" type="revolute">
        <parent link="pivot1" />
        <child link="arm1" />
        <axis xyz="1 0 0" />
        <limit lower="-1.57" upper="1.57" effort="30" velocity="1" />
    </joint>
    <joint name="arm1_to_pivot1b" type="continuous">
        <parent link="arm1" />
        <child link="pivot1b" />
        <origin xyz="0 0 7.5" rpy="0 0 0" />
        <axis xyz="0 0 1" />
    </joint>
    <joint name="pivot1b_to_arm1b" type="revolute">
        <parent link="pivot1b" />
        <child link="arm1b" />
        <axis xyz="1 0 0" />
        <limit lower="-1.57" upper="1.57" effort="30" velocity="1" />
    </joint>
    <joint name="arm1b_to_pivot2" type="continuous">
        <parent link="arm1b" />
        <child link="pivot2" />
        <origin xyz="0 0 7.5" rpy="0 0 0" />
        <axis xyz="0 0 1" />
    </joint>
    <joint name="pivot2_to_arm2" type="revolute">
        <parent link="pivot2" />
        <child link="arm2" />
        <axis xyz="1 0 0" />
        <limit lower="-1.57" upper="1.57" effort="30" velocity="1" />
    </joint>
    <joint name="arm2_to_sphere" type="fixed">
        <origin xyz="0 0 4.5" rpy="0 0 0" />
        <parent link="arm2" />
        <child link="sphere" />
    </joint>
    <joint name="sphere_to_needle" type="prismatic">
        <origin xyz="0 0 0" rpy="0 0 0" />
        <parent link="sphere" />
        <child link="needle" />
        <axis xyz="0 0 1" />
        <limit lower="0" upper="4" effort="10" velocity="1" />
    </joint>
    <transmission name="trans_base_link_to_rotator1">
        <type>transmission_interface/SimpleTransmission</type>
        <joint name="base_link_to_rotator1">
            <hardwareInterface>hardware_interface/EffortJointInterface</hardwareInterface>
        </joint>
        <actuator name="base_link_to_rotator1_motor">
            <hardwareInterface>hardware_interface/EffortJointInterface</hardwareInterface>
            <mechanicalReduction>1</mechanicalReduction>
        </actuator>
    </transmission>
    <transmission name="trans_pivot1_to_arm1">
        <type>transmission_interface/SimpleTransmission</type>
        <joint name="pivot1_to_arm1">
            <hardwareInterface>hardware_interface/EffortJointInterface</hardwareInterface>
        </joint>
        <actuator name="pivot1_to_arm1_motor">
            <hardwareInterface>hardware_interface/EffortJointInterface</hardwareInterface>
            <mechanicalReduction>1</mechanicalReduction>
        </actuator>
    </transmission>
    <transmission name="trans_arm1_to_pivot1b">
        <type>transmission_interface/SimpleTransmission</type>
        <joint name="arm1_to_pivot1b">
            <hardwareInterface>hardware_interface/EffortJointInterface</hardwareInterface>
        </joint>
        <actuator name="arm1_to_pivot1b_motor">
            <hardwareInterface>hardware_interface/EffortJointInterface</hardwareInterface>
            <mechanicalReduction>1</mechanicalReduction>
        </actuator>
    </transmission>
    <transmission name="trans_pivot1b_to_arm1b">
        <type>transmission_interface/SimpleTransmission</type>
        <joint name="pivot1b_to_arm1b">
            <hardwareInterface>hardware_interface/EffortJointInterface</hardwareInterface>
        </joint>
        <actuator name="pivot1b_to_arm1b_motor">
            <hardwareInterface>hardware_interface/EffortJointInterface</hardwareInterface>
            <mechanicalReduction>1</mechanicalReduction>
        </actuator>
    </transmission>
    <transmission name="trans_arm1b_to_pivot2">
        <type>transmission_interface/SimpleTransmission</type>
        <joint name="arm1b_to_pivot2">
            <hardwareInterface>hardware_interface/EffortJointInterface</hardwareInterface>
        </joint>
        <actuator name="arm1b_to_pivot2_motor">
            <hardwareInterface>hardware_interface/EffortJointInterface</hardwareInterface>
            <mechanicalReduction>1</mechanicalReduction>
        </actuator>
    </transmission>
    <transmission name="trans_pivot2_to_arm2">
        <type>transmission_interface/SimpleTransmission</type>
        <joint name="pivot2_to_arm2">
            <hardwareInterface>hardware_interface/EffortJointInterface</hardwareInterface>
        </joint>
        <actuator name="pivot2_to_arm2_motor">
            <hardwareInterface>hardware_interface/EffortJointInterface</hardwareInterface>
            <mechanicalReduction>1</mechanicalReduction>
        </actuator>
    </transmission>
    <transmission name="trans_sphere_to_needle">
        <type>transmission_interface/SimpleTransmission</type>
        <joint name="sphere_to_needle">
            <hardwareInterface>hardware_interface/EffortJointInterface</hardwareInterface>
        </joint>
        <actuator name="sphere_to_needle_motor">
            <hardwareInterface>hardware_interface/EffortJointInterface</hardwareInterface>
            <mechanicalReduction>1</mechanicalReduction>
        </actuator>
    </transmission>
    <gazebo>
        <plugin name="gazebo_ros_control">
            <robotNamespace>/</robotNamespace>
        </plugin>
    </gazebo>
</robot>

